Workbook
Name Slicer_Age: #N/A
Name Slicer_Gender: #N/A
Name Slicer_Social_Media_Platform: #N/A

Sheet Grup23_AnaVeri
A1: User_ID | B1: Age | C1: Daily_Screen_Time(hrs) | D1: Sleep_Quality(1-10) | E1: Stress_Level(1-10) | F1: Days_Without_Social_Media | G1: Exercise_Frequency(week) | H1: Happiness_Index(1-10) | I1: Gender | J1: Social_Media_Platform | K1: Yaş_Kategorisi
A2: U446 | B2: 16 | C2: 6.3 | D2: 6 | E2: 7 | F2: 6 | G2: 0 | H2: 8 | I2: Female | J2: Facebook | K2: =VLOOKUP(B2, Yaş_Grupları!$A$2:$B$6, 2, 1) -> Çocuk
A3: U483 | B3: 16 | C3: 5.7 | D3: 6 | E3: 6 | F3: 0 | G3: 2 | H3: 8 | I3: Female | J3: X (Twitter) | K3: =VLOOKUP(B3, Yaş_Grupları!$A$2:$B$6, 2, 1) -> Çocuk
A4: U315 | B4: 16 | C4: 5.3 | D4: 6 | E4: 6 | F4: 6 | G4: 0 | H4: 9 | I4: Female | J4: Facebook | K4: =VLOOKUP(B4, Yaş_Grupları!$A$2:$B$6, 2, 1) -> Çocuk
A5: U316 | B5: 16 | C5: 3.6 | D5: 7 | E5: 5 | F5: 5 | G5: 4 | H5: 10 | I5: Male | J5: TikTok | K5: =VLOOKUP(B5, Yaş_Grupları!$A$2:$B$6, 2, 1) -> Çocuk
A6: U465 | B6: 16 | C6: 3.5 | D6: 8 | E6: 5 | F6: 4 | G6: 3 | H6: 10 | I6: Female | J6: TikTok | K6: =VLOOKUP(B6, Yaş_Grupları!$A$2:$B$6, 2, 1) -> Çocuk
A7: U368 | B7: 16 | C7: 2.5 | D7: 8 | E7: 4 | F7: 4 | G7: 4 | H7: 10 | I7: Male | J7: YouTube | K7: =VLOOKUP(B7, Yaş_Grupları!$A$2:$B$6, 2, 1) -> Çocuk
A8: U213 | B8: 17 | C8: 9.8 | D8: 4 | E8: 9 | F8: 5 | G8: 0 | H8: 6 | I8: Female | J8: LinkedIn | K8: =VLOOKUP(B8, Yaş_Grupları!$A$2:$B$6, 2, 1) -> Çocuk
A9: U264 | B9: 17 | C9: 9.1 | D9: 4 | E9: 9 | F9: 7 | G9: 4 | H9: 4 | I9: Male | J9: TikTok | K9: =VLOOKUP(B9, Yaş_Grupları!$A$2:$B$6, 2, 1) -> Çocuk
A10: U266 | B10: 17 | C10: 8.7 | D10: 4 | E10: 8 | F10: 1 | G10: 1 | H10: 7 | I10: Male | J10: YouTube | K10: =VLOOKUP(B10, Yaş_Grupları!$A$2:$B$6, 2, 1) -> Çocuk
A11: U013 | B11: 17 | C11: 7 | D11: 7 | E11: 10 | F11: 7 | G11: 1 | H11: 8 | I11: Female | J11: YouTube | K11: =VLOOKUP(B11, Yaş_Grupları!$A$2:$B$6, 2, 1) -> Çocuk
A12: U013 | B12: 17 | C12: 7 | D12: 7 | E12: 10 | F12: 7 | G12: 1 | H12: 8 | I12: Female | J12: YouTube | K12: =VLOOKUP(B12, Yaş_Grupları!$A$2:$B$6, 2, 1) -> Çocuk
A13: U287 | B13: 17 | C13: 6.2 | D13: 6 | E13: 8 | F13: 0 | G13: 3 | H13: 7 | I13: Male | J13: YouTube | K13: =VLOOKUP(B13, Yaş_Grupları!$A$2:$B$6, 2, 1) -> Çocuk
... A401: U050 | B401: 49 | C401: 3.6 | D401: 7 | E401: 5 | F401: 4 | G401: 1 | H401: 9 | I401: Male | J401: TikTok | K401: =VLOOKUP(B401, Yaş_Grupları!$A$2:$B$6, 2, 1) -> Yetişkin

Sheet Yaş_Grupları
A1: 'Yaş_Alt_Sınır' (0, 18, 25, 35, 50) | B1: 'Yaş_Kategorisi' (Çocuk/Genç, Genç Yetişkin, Yetişkin, Orta Yaş)
A2: 0 | B2: Çocuk
A3: 18 | B3: Genç
A4: 25 | B4: Genç Yetişkin
A5: 35 | B5: Yetişkin
A6: 50 | B6: Orta Yaş

Sheet Pivot_Table
A3: Satır Etiketleri | B3: Ortalama Happiness_Index(1-10)
A4: 0 | B4: 8.3125
A5: 1 | B5: 8.4578313
A6: 2 | B6: 8.3431373
A7: 3 | B7: 8.1182796
A8: 4 | B8: 8.5245902
A9: 5 | B9: 8.9583333
A10: 6 | B10: 10
A11: 7 | B11: 10
A12: Genel Toplam | B12: 8.3975

Sheet OLAP_ANALİZ_YORUM
A3: Row Labels | B3: Ortalama Stress_Level(1-10) | C3: Ortalama Days_Without_Social_Media | N3: Row Labels | O3: Ortalama Stress_Level(1-10) | P3: Ortalama Days_Without_Social_Media
A4: Male | B4: 6.5526316 | C4: 3.1947368 | N4: Male
A5: 29 | B5: 5.875 | C5: 1.625 | N5: 16-19 | O5: 6.1176471 | P5: 2.5294118
A6: 18 | B6: 5.6 | C6: 2 | N6: 40-43 | O6: 6.4333333 | P6: 2.6666667
A7: 40 | B7: 6.6666667 | C7: 2.1111111 | N7: 28-31 | O7: 6.56 | P7: 2.72
A8: 42 | B8: 6.5 | C8: 2.1666667 | N8: 20-23 | O8: 6.3 | P8: 3.3
A9: 38 | B9: 6.875 | C9: 2.25 | N9: 36-39 | O9: 6.5789474 | P9: 3.3157895
A10: 23 | B10: 6 | C10: 2.375 | N10: 24-27 | O10: 6.9130435 | P10: 3.4782609
A11: 17 | B11: 7.6 | C11: 2.4 | N11: 48-51 | O11: 6.9166667 | P11: 3.5
A12: 19 | B12: 5.8 | C12: 2.4 | N12: 32-35 | O12: 6.9473684 | P12: 3.5263158
A13: 26 | B13: 7 | C13: 2.5 | N13: 44-47 | O13: 6.36 | P13: 3.92
A14: 30 | B14: 8 | C14: 2.5 | N14: Female | O14: 6.6865672 | P14: 2.9701493
A15: 27 | B15: 6.6666667 | C15: 2.6666667 | N15: Other | O15: 7.1111111 | P15: 4.2222222
A16: 35 | B16: 7.6 | C16: 2.8
A17: 22 | B17: 7 | C17: 3
A18: 28 | B18: 5.8 | C18: 3.2
A19: 41 | B19: 6.4 | C19: 3.2
A20: 43 | B20: 6 | C20: 3.2
A21: 25 | B21: 7.25 | C21: 3.25
A22: 32 | B22: 8.3333333 | C22: 3.3333333
A23: 34 | B23: 5.5 | C23: 3.3333333
A24: 44 | B24: 6.0769231 | C24: 3.4615385
A25: 49 | B25: 6.5 | C25: 3.5
A26: 37 | B26: 6.5 | C26: 3.5
A27: 48 | B27: 7.3333333 | C27: 3.5
... A38: 46 | B38: 7 | C38: 5
A39: Female | B39: 6.6865672 | C39: 2.9701493
A40: 25 | B40: 8 | C40: 0.5
A41: 45 | B41: 6.25 | C41: 1.25
A42: 42 | B42: 7.6 | C42: 1.4
A43: 30 | B43: 6 | C43: 1.5
A44: 18 | B44: 7 | C44: 1.7777778
A45: 26 | B45: 6.8333333 | C45: 2
A46: 20 | B46: 6.3333333 | C46: 2
A47: 39 | B47: 6.7 | C47: 2
A48: 41 | B48: 5.5 | C48: 2
A49: 28 | B49: 7 | C49: 2.2
A50: 43 | B50: 7.5555556 | C50: 2.3333333
A51: 46 | B51: 6.6 | C51: 2.4
... A71: 27 | B71: 7.3333333 | C71: 5.8333333
...

Sheet Grup_23_İstatistik_Özet
A1: Daily_Screen_Time(hrs) | C1: Sleep_Quality(1-10) | E1: Stress_Level(1-10)
A3: Mean | B3: 5.56775 | C3: Mean | D3: 6.345 | E3: Mean | F3: 6.6325
A4: Standard Error | B4: 0.087071326 | C4: Standard Error | D4: 0.075360038 | E4: Standard Error | F4: 0.076046479
A5: Median | B5: 5.7 | C5: Median | D5: 6 | E5: Median | F5: 7
A6: Mode | B6: 6.2 | C6: Mode | D6: 6 | E6: Mode | F6: 7
A7: Standard Deviation | B7: 1.7414265 | C7: Standard Deviation | D7: 1.5072008 | E7: Standard Deviation | F7: 1.5209296
A8: Sample Variance | B8: 3.0325664 | C8: Sample Variance | D8: 2.2716541 | E8: Sample Variance | F8: 2.3132268
A9: Kurtosis | B9: -0.12815334 | C9: Kurtosis | D9: -0.31253252 | E9: Kurtosis | F9: -0.11524795
A10: Skewness | B10: -0.012623733 | C10: Skewness | D10: 0.012845687 | E10: Skewness | F10: -0.011142919
A11: Range | B11: 9.8 | C11: Range | D11: 8 | E11: Range | F11: 8
A12: Minimum | B12: 1 | C12: Minimum | D12: 2 | E12: Minimum | F12: 2
A13: Maximum | B13: 10.8 | C13: Maximum | D13: 10 | E13: Maximum | F13: 10
A14: Sum | B14: 2227.1 | C14: Sum | D14: 2538 | E14: Sum | F14: 2653
A15: Count | B15: 400 | C15: Count | D15: 400 | E15: Count | F15: 400

Sheet Korelasyon Matrisi
A1: Daily_Screen_Time(hrs) | B1: Sleep_Quality(1-10) | C1: Stress_Level(1-10) | D1: Happiness_Index(1-10) | H1: Daily_Screen_Time(hrs) | I1: Sleep_Quality(1-10) | J1: Stress_Level(1-10) | K1: Happiness_Index(1-10)
A2: 10.8 | B2: 5 | C2: 10 | D2: 4 | G2: Daily_Screen_Time(hrs) | H2: 1
A3: 10 | B3: 3 | C3: 10 | D3: 4 | G3: Sleep_Quality(1-10) | H3: -0.76080375 | I3: 1
A4: 10 | B4: 3 | C4: 10 | D4: 4 | G4: Stress_Level(1-10) | H4: 0.73028887 | I4: -0.57758402 | J4: 1
A5: 10 | B5: 3 | C5: 10 | D5: 4 | G5: Happiness_Index(1-10) | H5: -0.67304899 | I5: 0.64546863 | J5: -0.72194853 | K5: 1
A6: 9.8 | B6: 4 | C6: 9 | D6: 6
A7: 9.7 | B7: 4 | C7: 8 | D7: 5
A8: 9.1 | B8: 4 | C8: 9 | D8: 7
A9: 9.1 | B9: 4 | C9: 9 | D9: 4
A10: 9 | B10: 4 | C10: 10 | D10: 4
A11: 9 | B11: 4 | C11: 10 | D11: 4
A12: 8.8 | B12: 2 | C12: 9 | D12: 7
A13: 8.8 | B13: 2 | C13: 9 | D13: 7
A14: 8.8 | B14: 4 | C14: 8 | D14: 6
A15: 8.8 | B15: 4 | C15: 8 | D15: 6
A16: 8.8 | B16: 4 | C16: 8 | D16: 6
A17: 8.7 | B17: 6 | C17: 7 | D17: 10
... A401: 1 | B401: 7 | C401: 5 | D401: 10

Sheet Grup23_DASHBOARD
